Workbook

Sheet Index
A1: SOW Effort-Scoping Calculators — Index
A2: One calculator per product line, all in the same Assumptions → Calculator → Result format. Start with Global Assumptions to set the shared rate, PM %, and timeline multipliers used across every tab below.
A4: Tab | B4: What's included | C4: Go to
A5: GLOBAL
A6: Global Assumptions | B6: Shared blended rate, standard 35% PM rule, short-timeline multipliers, and process reminders referenced by every tab below. | C6: Open tab →
A7: CORE IMPLEMENTATION
A8: Support | B8: Zendesk Support setup — discovery by agent-group tier, business-rule build scaled by count, Guide OOB, action-flow add-ons. | C8: Open tab →
A9: DC | B9: Dynamic Content / localization setup, scaled by # of custom items and # of languages (cascading Low/Mid/High tiers). | C9: Open tab →
A10: Multi Brand | B10: Configuring additional brands within a single Zendesk instance. | C10: Open tab →
A11: Custom HC | B11: ⚠ PLACEHOLDER — Custom Help Center theming/branding, structure, and legacy content migration. No benchmark SOW available yet. | C11: Open tab →
A12: CHANNELS
A13: Voice | B13: Zendesk Talk OOB setup — phone numbers, IVR build by complexity, training/testing. No PM applied. | C13: Open tab →
A14: OOB Messaging | B14: Messaging widget setup (web + other channels like WhatsApp/FB) per brand, plus optional TA guidance. | C14: Open tab →
A15: AI & AUTOMATION
A16: AI Copilot | B16: Two tiers: turning on Copilot features only, or the fuller tier with procedures/config. No PM on the enable-only tier. | C16: Open tab →
A17: AIAA | B17: AI Agents/Advanced Automation — source connection, up to 3 use cases, included API connections, support routing, TA guidance. PM only above 40 hrs. | C17: Open tab →
A18: QUALITY & WORKFORCE
A19: QA | B19: Scorecards, workspaces, AutoQA, Spotlight, calibration/coaching methodology, dashboards, config. No PM applied. | C19: Open tab →
A20: WFM | B20: Workforce Management setup — discovery, config, UAT/training, hypercare, up to 4 workstreams included. | C20: Open tab →
A21: DATA, SECURITY & CUSTOM DEVELOPMENT
A22: Adv Data Privacy | B22: Advanced encryption/BYOK — quick Feature Review, or the full 6-phase KMS implementation. | C22: Open tab →
A23: custom objects | B23: Zendesk Custom Object scope — data model design, build, object-facing UI, migration into objects. | C23: Open tab →
A24: Migration | B24: Ticket/user/org/attachment data migration into Zendesk — mapping, volume, attachments, open-ticket delta handling. | C24: Open tab →
A25: Custom App | B25: Custom Zendesk apps/integrations — sidebar apps, ticket-sidebar widgets, backend integrations (e.g. Envoy Connect). | C25: Open tab →
A26: ANALYTICS & ADD-ONS
A27: Analytics | B27: Explore reporting setup — baseline dashboard/reports/metrics allowance, additional units, optional training session. | C27: Open tab →
A28: Public Slack | B28: 8% modifier on a project's PM + Consultant time for projects that include public Slack channel support. | C28: Open tab →

Sheet Global Assumptions
A1: Global Assumptions & Rules
A2: Shared defaults referenced by every product tab in this workbook. Tabs marked with a green link cell pull their rate directly from here; tabs with their own established rate (custom objects, Migration, Custom App) keep a local rate since those were deliberately set at different levels. Edit values here to update every linked tab at once.
A4: SHARED DEFAULTS
A5: Assumption | B5: Value | C5: Notes / Source
A6: Default blended hourly rate ($) | B6: 258 | C6: Reference rate for any tab that doesn't already have its own established rate. Roughly the midpoint of the three existing calculators' rates ($258 custom objects / $235 Migration / $253 Custom App).
A7: Standard PM % of project hours | B7: 0.35 | C7: From the original Notes tab: "35% for PM." Applied to total project hours on every tab unless that tab documents an explicit exception (see that tab's Assumptions section).
A9: SHORT-TIMELINE MULTIPLIER (select the delivery timeline on each tab's Result section)
A10: Multiplier — Standard (7+ weeks) | B10: 1 | C10: Baseline, no compression.
A11: Multiplier — 5-7 weeks | B11: 1.2 | C11: From the original Notes tab.
A12: Multiplier — 3-4 weeks | B12: 1.3 | C12: From the original Notes tab.
A13: Multiplier — <3 weeks | B13: 1.4 | C13: From the original Notes tab. Note: will also likely require multiple resources — a timeline this compressed may need a staffing conversation, not just a rate adjustment.
A14: Standalone engagement — KO (0.5h) + design sign-off (0.5h) flat hrs | B14: 1 | C14: Reference only — informational. Applies when a product engagement is sold on its own, not bundled into a Support package: a 30-min kickoff plus a 30-min design sign-off session. Each product tab notes this in its Meeting Cadence section; it is not automatically added to any tab's hours.
A16: PROCESS REMINDERS (apply when assembling the actual SOW document)
A17: • Update the SOW whenever an expected item is not included in scope — don't let an exclusion go unstated.
A18: • The signer needs to initial on any items that are explicitly called out as included, per client sign-off practice.
A19: • "Update weeks of performance" — confirm the period-of-performance language reflects the actual timeline used for the short-timeline multiplier above.
A21: PER-TAB PM EXCEPTIONS (documented overrides to the 35% standard)
A22: Tab | B22: Exception
A23: Voice | B23: No PM needed for this part.
A24: QA | B24: No PM needed for this part.
A25: AIAA | B25: No PM needed if standalone and under 40 total hours; projects over 40 hours should include a PM.
A26: AI Copilot | B26: No PM needed for the "turning on features only" tier.

Sheet Support
A1: Support Implementation Calculator
A2: WHAT'S INCLUDED: Core Zendesk Support setup — discovery by agent-group tier, business-rule (trigger/automation) build scaled by count, optional Guide OOB knowledge base setup, and action-flow add-ons. Groups beyond the first 3 add discovery and configuration effort (see below). Email and forms are the channels covered here; see the Voice and OOB Messaging tabs for those channels.
A4: MEETING CADENCE (informational — already reflected in the effort hours below; not additive)
A5: • Up to 3 discovery sessions (Standard tier) / up to 6 (Higher tier), plus up to 2 additional discovery sessions per group beyond 3, per the Discovery hours below.
A6: • Up to 1 collaboration meeting for Knowledge/Help Center (Guide).
A7: • Up to 1 UAT meeting.
A8: • Up to 1 UAT feedback meeting.
A9: • Up to 1 go-live checklist review meeting.
A10: • Up to 1×30-min kickoff (KO).
A12: SECTION 1 — ASSUMPTIONS (gray = calibrated reference values, not meant to be edited)
A13: Assumption | B13: Value | C13: Notes / Source
A14: Blended hourly rate ($) | B14: ='Global Assumptions'!$B$6 -> 258 | C14: Linked to Global Assumptions default rate.
A16: DISCOVERY (per agent-group tier)
A17: Discovery hrs — Standard tier (up to 3 discovery sessions, 12 agent teams, 2 agents) | B17: 3 | C17: From the original Support rate card.
A18: Discovery hrs — Higher tier (up to 6 discovery sessions, 22 agent teams, 2 agents) | B18: 6 | C18: From the original Support rate card.
A20: GROUPS BEYOND 3 (additional discovery + configuration effort)
A21: # groups included before additional effort kicks in | B21: 3 | C21: New.
A22: Additional discovery hrs per group beyond 3 (up to 2 meetings) | B22: 2 | C22: New.
A23: Additional configuration/business-rule hrs per group beyond 3 | B23: 3 | C23: New.
A25: BUSINESS RULES (triggers/automations — tiered by count, includes build/testing/hypercare)
A26: Hrs — up to 25 business rules | B26: 15 | C26: ≈0.6 hrs/rule.
A27: Hrs — up to 55 business rules* | B27: 20 | C27: *Includes two action flows. ≈0.36 hrs/rule.
A28: Hrs — up to 85 business rules* | B28: 30 | C28: *Includes two action flows. ≈0.35 hrs/rule.
A29: Hrs — up to 100 business rules (custom) | B29: 35 | C29: Beyond 100, treat as fully custom scoping.
A31: GUIDE / KNOWLEDGE BASE (out-of-the-box)
A32: Guide OOB setup — flat hrs | B32: 10 | C32: Includes new features like Knowledge builder.
A34: ADD-ONS
A35: Additional action flow — hrs each | B35: 4 | C35: Beyond what's included in the Business Rules tier above.
A37: SECTION 2 — CALCULATOR (add one row per scope; only edit columns A—F)
A38: Row below marked EXAMPLE is a sample entry — overwrite it. Columns G onward calculate automatically.
A39: Scope Name | B39: Discovery Tier | C39: # Groups | D39: # Business Rules | E39: Include Guide OOB? (Y/N) | F39: # Additional Action Flows | G39: Discovery Hrs | H39: Business Rules Hrs | I39: Guide Hrs | J39: Add-on Hrs | K39: Total Hrs | L39: Total Cost ($)
A40: Support Implementation (EXAMPLE — overwrite) | B40: Standard | C40: 3 | D40: 40 | E40: Y | F40: 1 | G40: =IF($A40="","",IF($B40="Higher",$B$18,$B$17)+MAX(0,$C40-$B$21)*$B$22) -> 3 | H40: =IF($A40="","",IF($D40<=25,$B$26,IF($D40<=55,$B$27,IF($D40<=85,$B$28,$B$29)))+MAX(0,$C40-$B$21)*$B$23) -> 20 | I40: =IF($A40="","",IF($E40="Y",$B$32,0)) -> 10 | J40: =IF($A40="","",$F40*$B$35) -> 4 | K40: =IF($A40="","",$G40+$H40+$I40+$J40) -> 37 | L40: =IF($A40="","",$K40*'Global Assumptions'!$B$6) -> 9546
G41: =IF($A41="","",IF($B41="Higher",$B$18,$B$17)+MAX(0,$C41-$B$21)*$B$22) | H41: =IF($A41="","",IF($D41<=25,$B$26,IF($D41<=55,$B$27,IF($D41<=85,$B$28,$B$29)))+MAX(0,$C41-$B$21)*$B$23) | I41: =IF($A41="","",IF($E41="Y",$B$32,0)) | J41: =IF($A41="","",$F41*$B$35) | K41: =IF($A41="","",$G41+$H41+$I41+$J41) | L41: =IF($A41="","",$K41*'Global Assumptions'!$B$6)
G42: =IF($A42="","",IF($B42="Higher",$B$18,$B$17)+MAX(0,$C42-$B$21)*$B$22) | H42: =IF($A42="","",IF($D42<=25,$B$26,IF($D42<=55,$B$27,IF($D42<=85,$B$28,$B$29)))+MAX(0,$C42-$B$21)*$B$23) | I42: =IF($A42="","",IF($E42="Y",$B$32,0)) | J42: =IF($A42="","",$F42*$B$35) | K42: =IF($A42="","",$G42+$H42+$I42+$J42) | L42: =IF($A42="","",$K42*'Global Assumptions'!$B$6)
G43: =IF($A43="","",IF($B43="Higher",$B$18,$B$17)+MAX(0,$C43-$B$21)*$B$22) | H43: =IF($A43="","",IF($D43<=25,$B$26,IF($D43<=55,$B$27,IF($D43<=85,$B$28,$B$29)))+MAX(0,$C43-$B$21)*$B$23) | I43: =IF($A43="","",IF($E43="Y",$B$32,0)) | J43: =IF($A43="","",$F43*$B$35) | K43: =IF($A43="","",$G43+$H43+$I43+$J43) | L43: =IF($A43="","",$K43*'Global Assumptions'!$B$6)
G44: =IF($A44="","",IF($B44="Higher",$B$18,$B$17)+MAX(0,$C44-$B$21)*$B$22) | H44: =IF($A44="","",IF($D44<=25,$B$26,IF($D44<=55,$B$27,IF($D44<=85,$B$28,$B$29)))+MAX(0,$C44-$B$21)*$B$23) | I44: =IF($A44="","",IF($E44="Y",$B$32,0)) | J44: =IF($A44="","",$F44*$B$35) | K44: =IF($A44="","",$G44+$H44+$I44+$J44) | L44: =IF($A44="","",$K44*'Global Assumptions'!$B$6)
G45: =IF($A45="","",IF($B45="Higher",$B$18,$B$17)+MAX(0,$C45-$B$21)*$B$22) | H45: =IF($A45="","",IF($D45<=25,$B$26,IF($D45<=55,$B$27,IF($D45<=85,$B$28,$B$29)))+MAX(0,$C45-$B$21)*$B$23) | I45: =IF($A45="","",IF($E45="Y",$B$32,0)) | J45: =IF($A45="","",$F45*$B$35) | K45: =IF($A45="","",$G45+$H45+$I45+$J45) | L45: =IF($A45="","",$K45*'Global Assumptions'!$B$6)
G46: =IF($A46="","",IF($B46="Higher",$B$18,$B$17)+MAX(0,$C46-$B$21)*$B$22) | H46: =IF($A46="","",IF($D46<=25,$B$26,IF($D46<=55,$B$27,IF($D46<=85,$B$28,$B$29)))+MAX(0,$C46-$B$21)*$B$23) | I46: =IF($A46="","",IF($E46="Y",$B$32,0)) | J46: =IF($A46="","",$F46*$B$35) | K46: =IF($A46="","",$G46+$H46+$I46+$J46) | L46: =IF($A46="","",$K46*'Global Assumptions'!$B$6)
G47: =IF($A47="","",IF($B47="Higher",$B$18,$B$17)+MAX(0,$C47-$B$21)*$B$22) | H47: =IF($A47="","",IF($D47<=25,$B$26,IF($D47<=55,$B$27,IF($D47<=85,$B$28,$B$29)))+MAX(0,$C47-$B$21)*$B$23) | I47: =IF($A47="","",IF($E47="Y",$B$32,0)) | J47: =IF($A47="","",$F47*$B$35) | K47: =IF($A47="","",$G47+$H47+$I47+$J47) | L47: =IF($A47="","",$K47*'Global Assumptions'!$B$6)
G48: =IF($A48="","",IF($B48="Higher",$B$18,$B$17)+MAX(0,$C48-$B$21)*$B$22) | H48: =IF($A48="","",IF($D48<=25,$B$26,IF($D48<=55,$B$27,IF($D48<=85,$B$28,$B$29)))+MAX(0,$C48-$B$21)*$B$23) | I48: =IF($A48="","",IF($E48="Y",$B$32,0)) | J48: =IF($A48="","",$F48*$B$35) | K48: =IF($A48="","",$G48+$H48+$I48+$J48) | L48: =IF($A48="","",$K48*'Global Assumptions'!$B$6)
...

Sheet DC
A1: Dynamic Content Calculator
A2: WHAT'S INCLUDED: Localization/translation setup for dynamic content items (macros, triggers, articles, etc.) across one or more languages. Effort tiers cascade: Mid = Low base × 1.5, High = Mid × 1.25 — reflecting the real structure of the original rate card.
A4: MEETING CADENCE (informational — already reflected in the effort hours below; not additive)
A5: • If this engagement is standalone (not bundled with a Support package): +30-min kickoff, +30-min design sign-off (see Global Assumptions).
A7: SECTION 1 — ASSUMPTIONS (gray = calibrated reference values, not meant to be edited)
A8: Assumption | B8: Value | C8: Notes / Source
A9: Blended hourly rate ($) | B9: ='Global Assumptions'!$B$6 -> 258 | C9: Linked to Global Assumptions default rate.
A11: TIER THRESHOLDS (by # of custom items)
A12: Low tier — up to # items | B12: 40 | C12: From the original DC rate card.
A13: Mid tier — up to # items | B13: 85 | C13: From the original DC rate card.
A14: High tier — up to # items | B14: 200 | C14: From the original DC rate card. Beyond this, treat as fully custom scoping.
A16: BASE HOURS (Low tier)
A17: Low tier base hrs — under 5 languages | B17: 10 | C17: From the original DC rate card.
A18: Low tier base hrs — 5+ languages | B18: 20 | C18: From the original DC rate card.
A20: CASCADING MULTIPLIERS
A21: Mid tier multiplier (applied to Low base) | B21: 1.5 | C21: Mid = Low base × this multiplier (10×1.5=15; 20×1.5=30 — matches the original rate card exactly).
A22: High tier multiplier (applied to Mid base) | B22: 1.25 | C22: High = Mid base × this multiplier (15×1.25=18.75; 30×1.25=37.5 — matches the original rate card exactly).
A24: SECTION 2 — CALCULATOR (add one row per scope; only edit columns A—C)
A25: Row below marked EXAMPLE is a sample entry — overwrite it. Columns D onward calculate automatically.
A26: Scope Name | B26: # Custom Items | C26: # Languages | D26: Tier (computed) | E26: Base Hrs (Low) | F26: Tier Hrs | G26: — | H26: Total Hrs | I26: Total Cost ($)
A27: Macro Translation (EXAMPLE — overwrite) | B27: 60 | C27: 3 | D27: =IF($A27="","",IF($B27<=$B$12,"Low",IF($B27<=$B$13,"Mid","High"))) -> Mid | E27: =IF($A27="","",IF($C27<5,$B$17,$B$18)) -> 10 | F27: =IF($A27="","",IF($D27="Low",$E27,IF($D27="Mid",$E27*$B$21,$E27*$B$21*$B$22))) -> 15 | H27: =IF($A27="","",$F27) -> 15 | I27: =IF($A27="","",$H27*'Global Assumptions'!$B$6) -> 3870
D28: =IF($A28="","",IF($B28<=$B$12,"Low",IF($B28<=$B$13,"Mid","High"))) | E28: =IF($A28="","",IF($C28<5,$B$17,$B$18)) | F28: =IF($A28="","",IF($D28="Low",$E28,IF($D28="Mid",$E28*$B$21,$E28*$B$21*$B$22))) | H28: =IF($A28="","",$F28) | I28: =IF($A28="","",$H28*'Global Assumptions'!$B$6)
D29: =IF($A29="","",IF($B29<=$B$12,"Low",IF($B29<=$B$13,"Mid","High"))) | E29: =IF($A29="","",IF($C29<5,$B$17,$B$18)) | F29: =IF($A29="","",IF($D29="Low",$E29,IF($D29="Mid",$E29*$B$21,$E29*$B$21*$B$22))) | H29: =IF($A29="","",$F29) | I29: =IF($A29="","",$H29*'Global Assumptions'!$B$6)
D30: =IF($A30="","",IF($B30<=$B$12,"Low",IF($B30<=$B$13,"Mid","High"))) | E30: =IF($A30="","",IF($C30<5,$B$17,$B$18)) | F30: =IF($A30="","",IF($D30="Low",$E30,IF($D30="Mid",$E30*$B$21,$E30*$B$21*$B$22))) | H30: =IF($A30="","",$F30) | I30: =IF($A30="","",$H30*'Global Assumptions'!$B$6)
D31: =IF($A31="","",IF($B31<=$B$12,"Low",IF($B31<=$B$13,"Mid","High"))) | E31: =IF($A31="","",IF($C31<5,$B$17,$B$18)) | F31: =IF($A31="","",IF($D31="Low",$E31,IF($D31="Mid",$E31*$B$21,$E31*$B$21*$B$22))) | H31: =IF($A31="","",$F31) | I31: =IF($A31="","",$H31*'Global Assumptions'!$B$6)
D32: =IF($A32="","",IF($B32<=$B$12,"Low",IF($B32<=$B$13,"Mid","High"))) | E32: =IF($A32="","",IF($C32<5,$B$17,$B$18)) | F32: =IF($A32="","",IF($D32="Low",$E32,IF($D32="Mid",$E32*$B$21,$E32*$B$21*$B$22))) | H32: =IF($A32="","",$F32) | I32: =IF($A32="","",$H32*'Global Assumptions'!$B$6)
D33: =IF($A33="","",IF($B33<=$B$12,"Low",IF($B33<=$B$13,"Mid","High"))) | E33: =IF($A33="","",IF($C33<5,$B$17,$B$18)) | F33: =IF($A33="","",IF($D33="Low",$E33,IF($D33="Mid",$E33*$B$21,$E33*$B$21*$B$22))) | H33: =IF($A33="","",$F33) | I33: =IF($A33="","",$H33*'Global Assumptions'!$B$6)
D34: =IF($A34="","",IF($B34<=$B$12,"Low",IF($B34<=$B$13,"Mid","High"))) | E34: =IF($A34="","",IF($C34<5,$B$17,$B$18)) | F34: =IF($A34="","",IF($D34="Low",$E34,IF($D34="Mid",$E34*$B$21,$E34*$B$21*$B$22))) | H34: =IF($A34="","",$F34) | I34: =IF($A34="","",$H34*'Global Assumptions'!$B$6)
D35: =IF($A35="","",IF($B35<=$B$12,"Low",IF($B35<=$B$13,"Mid","High"))) | E35: =IF($A35="","",IF($C35<5,$B$17,$B$18)) | F35: =IF($A35="","",IF($D35="Low",$E35,IF($D35="Mid",$E35*$B$21,$E35*$B$21*$B$22))) | H35: =IF($A35="","",$F35) | I35: =IF($A35="","",$H35*'Global Assumptions'!$B$6)
D36: =IF($A36="","",IF($B36<=$B$12,"Low",IF($B36<=$B$13,"Mid","High"))) | E36: =IF($A36="","",IF($C36<5,$B$17,$B$18)) | F36: =IF($A36="","",IF($D36="Low",$E36,IF($D36="Mid",$E36*$B$21,$E36*$B$21*$B$22))) | H36: =IF($A36="","",$F36) | I36: =IF($A36="","",$H36*'Global Assumptions'!$B$6)
A37: TOTAL | B37: =SUM(B27:B36) -> 60 | C37: =SUM(C27:C36) -> 3 | H37: =SUM(H27:H36) -> 15 | I37: =SUM(I27:I36) -> 3870
A39: SECTION 3 — RESULT
A40: Total hours (pre-PM) | B40: =$H$37 -> 15
A41: PM hours | B41: =IF($B$40=0,0,$B$40*'Global Assumptions'!$B$7) -> 5.25
A42: Project timeline (select) | B42: Standard (7+ weeks)
A43: Final hours (incl. PM + timeline multiplier) | B43: =($B$40+$B$41)*IF($B$42="5-7 weeks",'Global Assumptions'!$B$11,IF($B$42="3-4 weeks",'Global Assumptions'!$B$12,IF($B$42="<3 weeks",'Global Assumptions'!$B$13,'Global Assumptions'!$B$10))) -> 20.25
A44: Final cost ($) | B44: =$B$43*'Global Assumptions'!$B$6 -> 5224.5
A46: Sources reviewed: original Sow Collab "DC" tab (cascading Low/Mid/High tier multipliers by item count and language count).

Sheet Multi Brand
A1: Multi-Brand Calculator
A2: WHAT'S INCLUDED: Configuring additional brands within a single Zendesk instance. Flat allowance covers up to 3 brands; each brand beyond that is a flat add.
A4: MEETING CADENCE (informational — already reflected in the effort hours below; not additive)
A5: • Up to 1hr additional discovery session.
A6: • If this engagement is standalone (not bundled with a Support package): +30-min kickoff, +30-min design sign-off (see Global Assumptions).
A8: SECTION 1 — ASSUMPTIONS (gray = calibrated reference values, not meant to be edited)
A9: Assumption | B9: Value | C9: Notes / Source
A10: Blended hourly rate ($) | B10: ='Global Assumptions'!$B$6 -> 258 | C10: Linked to Global Assumptions default rate.
A12: Flat hrs — included, up to 3 brands | B12: 5 | C12: From the original Multi Brand rate card.
A13: # brands included in the flat allowance | B13: 3 | C13: From the original Multi Brand rate card.
A14: Hrs per additional brand (beyond the included allowance) | B14: 5 | C14: From the original Multi Brand rate card.
A16: SECTION 2 — CALCULATOR (add one row per scope; only edit columns A—B)
A17: Row below marked EXAMPLE is a sample entry — overwrite it. Columns C onward calculate automatically.
A18: Scope Name | B18: # Total Brands | C18: Additional Brands | D18: — | E18: — | F18: Total Hrs | G18: Total Cost ($)
A19: Multi-Brand Setup (EXAMPLE — overwrite) | B19: 5 | C19: =IF($A19="","",MAX(0,$B19-$B$13)) -> 2 | F19: =IF($A19="","",$B$12+$C19*$B$14) -> 15 | G19: =IF($A19="","",$F19*'Global Assumptions'!$B$6) -> 3870
C20: =IF($A20="","",MAX(0,$B20-$B$13)) | F20: =IF($A20="","",$B$12+$C20*$B$14) | G20: =IF($A20="","",$F20*'Global Assumptions'!$B$6)
C21: =IF($A21="","",MAX(0,$B21-$B$13)) | F21: =IF($A21="","",$B$12+$C21*$B$14) | G21: =IF($A21="","",$F21*'Global Assumptions'!$B$6)
C22: =IF($A22="","",MAX(0,$B22-$B$13)) | F22: =IF($A22="","",$B$12+$C22*$B$14) | G22: =IF($A22="","",$F22*'Global Assumptions'!$B$6)
C23: =IF($A23="","",MAX(0,$B23-$B$13)) | F23: =IF($A23="","",$B$12+$C23*$B$14) | G23: =IF($A23="","",$F23*'Global Assumptions'!$B$6)
C24: =IF($A24="","",MAX(0,$B24-$B$13)) | F24: =IF($A24="","",$B$12+$C24*$B$14) | G24: =IF($A24="","",$F24*'Global Assumptions'!$B$6)
C25: =IF($A25="","",MAX(0,$B25-$B$13)) | F25: =IF($A25="","",$B$12+$C25*$B$14) | G25: =IF($A25="","",$F25*'Global Assumptions'!$B$6)
C26: =IF($A26="","",MAX(0,$B26-$B$13)) | F26: =IF($A26="","",$B$12+$C26*$B$14) | G26: =IF($A26="","",$F26*'Global Assumptions'!$B$6)
C27: =IF($A27="","",MAX(0,$B27-$B$13)) | F27: =IF($A27="","",$B$12+$C27*$B$14) | G27: =IF($A27="","",$F27*'Global Assumptions'!$B$6)
C28: =IF($A28="","",MAX(0,$B28-$B$13)) | F28: =IF($A28="","",$B$12+$C28*$B$14) | G28: =IF($A28="","",$F28*'Global Assumptions'!$B$6)
A29: TOTAL | F29: =SUM(F19:F28) -> 15 | G29: =SUM(G19:G28) -> 3870
A31: SECTION 3 — RESULT
A32: Total hours (pre-PM) | B32: =$F$29 -> 15
A33: PM hours | B33: =IF($B$32=0,0,$B$32*'Global Assumptions'!$B$7) -> 5.25
A34: Project timeline (select) | B34: Standard (7+ weeks)
A35: Final hours (incl. PM + timeline multiplier) | B35: =($B$32+$B$33)*IF($B$34="5-7 weeks",'Global Assumptions'!$B$11,IF($B$34="3-4 weeks",'Global Assumptions'!$B$12,IF($B$34="<3 weeks",'Global Assumptions'!$B$13,'Global Assumptions'!$B$10))) -> 20.25
A36: Final cost ($) | B36: =$B$35*'Global Assumptions'!$B$6 -> 5224.5
A38: Sources reviewed: original Sow Collab "Multi Brand" tab.

Sheet Custom HC
A1: Custom Help Center Calculator ⚠ PARTIAL PLACEHOLDER
A2: WHAT'S INCLUDED: Custom-themed Help Center (Guide) design/build beyond the out-of-the-box setup already covered on the Support tab — Design and Build/Development are scoped as separate line items, plus category/section structure and legacy content migration. ⚠ Reviewed past Guide SOWs (Everlink SOW 004, the Zimperium proposal, Zendesk Inc./GoFundMe/Gameday Men's Health) for a Design-vs-Build hour split — none itemize hours by phase; they're either fixed-fee totals or phase/round counts without hours. Everlink SOW 004's Guide build was a $6,740 fixed fee (≈27 hrs at $253/hr blended) for a smaller-scope "Guide Updates" engagement — notably less than the 45 hrs (15 Design + 30 Build) below, though scope wasn't identical. Treat the 15/30 split as directional until a matching real SOW is available.
A4: MEETING CADENCE (informational — already reflected in the effort hours below; not additive)
A5: • Up to 2×1hr discovery sessions reviewing an existing Figma file (real benchmark: Zendesk Inc. SOW 002, GoFundMe SOW 006).
A6: • Up to 2 rounds of revisions each on Home/Article pages and interior pages, plus a mobile landing/article page.
A7: • If this engagement is standalone (not bundled with a Support package): +30-min kickoff, +30-min design sign-off (see Global Assumptions).
A9: SECTION 1 — ASSUMPTIONS (gray = calibrated reference values, not meant to be edited — PLACEHOLDER VALUES)
A10: Assumption | B10: Value | C10: Notes / Source
A11: Blended hourly rate ($) | B11: ='Global Assumptions'!$B$6 -> 258 | C11: Linked to Global Assumptions default rate.
A13: DESIGN
A14: Design — flat hrs | B14: 10 | C14: PLACEHOLDER — see title note above; no matching past-SOW hour breakdown found. Figma design work, distinct from front-end build.
A16: BUILD / DEVELOPMENT
A17: Build/Development — flat hrs | B17: 25 | C17: PLACEHOLDER — see title note above. HTML/CSS front-end development of the approved design.
A19: STRUCTURE
A20: Hrs per category/section | B20: 0.25 | C20: PLACEHOLDER — no source SOW. Estimate only.
A22: CONTENT MIGRATION
A23: Hrs per 50 legacy articles migrated | B23: 2 | C23: PLACEHOLDER — no source SOW. Estimate only.
A25: MULTI-BRAND HELP CENTER
A26: Additional hrs per brand (beyond first) | B26: 25 | C26: PLACEHOLDER — no source SOW; set equal to the Multi Brand tab's per-brand rate as a starting point.
A28: SECTION 2 — CALCULATOR (add one row per scope; only edit columns A—D)
A29: Row below marked EXAMPLE is a sample entry — overwrite it. Columns E onward calculate automatically.
A30: Scope Name | B30: # Categories/ Sections | C30: # Legacy Articles to Migrate | D30: # Brands | E30: Design Hrs | F30: Build Hrs | G30: Structure Hrs | H30: Migration Hrs | I30: Total Hrs | J30: Total Cost ($)
A31: Custom Help Center Build (EXAMPLE — overwrite) | B31: 12 | C31: 150 | D31: 1 | E31: =IF($A31="","",$B$14) -> 10 | F31: =IF($A31="","",$B$17+MAX(0,$D31-1)*$B$26) -> 25 | G31: =IF($A31="","",$B31*$B$20) -> 3 | H31: =IF($A31="","",($C31/50)*$B$23) -> 6 | I31: =IF($A31="","",$E31+$F31+$G31+$H31) -> 44 | J31: =IF($A31="","",$I31*'Global Assumptions'!$B$6) -> 11352
E32: =IF($A32="","",$B$14) | F32: =IF($A32="","",$B$17+MAX(0,$D32-1)*$B$26) | G32: =IF($A32="","",$B32*$B$20) | H32: =IF($A32="","",($C32/50)*$B$23) | I32: =IF($A32="","",$E32+$F32+$G32+$H32) | J32: =IF($A32="","",$I32*'Global Assumptions'!$B$6)
E33: =IF($A33="","",$B$14) | F33: =IF($A33="","",$B$17+MAX(0,$D33-1)*$B$26) | G33: =IF($A33="","",$B33*$B$20) | H33: =IF($A33="","",($C33/50)*$B$23) | I33: =IF($A33="","",$E33+$F33+$G33+$H33) | J33: =IF($A33="","",$I33*'Global Assumptions'!$B$6)
E34: =IF($A34="","",$B$14) | F34: =IF($A34="","",$B$17+MAX(0,$D34-1)*$B$26) | G34: =IF($A34="","",$B34*$B$20) | H34: =IF($A34="","",($C34/50)*$B$23) | I34: =IF($A34="","",$E34+$F34+$G34+$H34) | J34: =IF($A34="","",$I34*'Global Assumptions'!$B$6)
E35: =IF($A35="","",$B$14) | F35: =IF($A35="","",$B$17+MAX(0,$D35-1)*$B$26) | G35: =IF($A35="","",$B35*$B$20) | H35: =IF($A35="","",($C35/50)*$B$23) | I35: =IF($A35="","",$E35+$F35+$G35+$H35) | J35: =IF($A35="","",$I35*'Global Assumptions'!$B$6)
E36: =IF($A36="","",$B$14) | F36: =IF($A36="","",$B$17+MAX(0,$D36-1)*$B$26) | G36: =IF($A36="","",$B36*$B$20) | H36: =IF($A36="","",($C36/50)*$B$23) | I36: =IF($A36="","",$E36+$F36+$G36+$H36) | J36: =IF($A36="","",$I36*'Global Assumptions'!$B$6)
E37: =IF($A37="","",$B$14) | F37: =IF($A37="","",$B$17+MAX(0,$D37-1)*$B$26) | G37: =IF($A37="","",$B37*$B$20) | H37: =IF($A37="","",($C37/50)*$B$23) | I37: =IF($A37="","",$E37+$F37+$G37+$H37) | J37: =IF($A37="","",$I37*'Global Assumptions'!$B$6)
E38: =IF($A38="","",$B$14) | F38: =IF($A38="","",$B$17+MAX(0,$D38-1)*$B$26) | G38: =IF($A38="","",$B38*$B$20) | H38: =IF($A38="","",($C38/50)*$B$23) | I38: =IF($A38="","",$E38+$F38+$G38+$H38) | J38: =IF($A38="","",$I38*'Global Assumptions'!$B$6)
E39: =IF($A39="","",$B$14) | F39: =IF($A39="","",$B$17+MAX(0,$D39-1)*$B$26) | G39: =IF($A39="","",$B39*$B$20) | H39: =IF($A39="","",($C39/50)*$B$23) | I39: =IF($A39="","",$E39+$F39+$G39+$H39) | J39: =IF($A39="","",$I39*'Global Assumptions'!$B$6)
E40: =IF($A40="","",$B$14) | F40: =IF($A40="","",$B$17+MAX(0,$D40-1)*$B$26) | G40: =IF($A40="","",$B40*$B$20) | H40: =IF($A40="","",($C40/50)*$B$23) | I40: =IF($A40="","",$E40+$F40+$G40+$H40) | J40: =IF($A40="","",$I40*'Global Assumptions'!$B$6)
A41: TOTAL | B41: =SUM(B31:B40) -> 12 | C41: =SUM(C31:C40) -> 150 | D41: =SUM(D31:D40) -> 1 | E41: =SUM(E31:E40) -> 10 | F41: =SUM(F31:F40) -> 25 | G41: =SUM(G31:G40) -> 3 | H41: =SUM(H31:H40) -> 6 | I41: =SUM(I31:I40) -> 44 | J41: =SUM(J31:J40) -> 11352
A43: SECTION 3 — RESULT
A44: Total hours (pre-PM) | B44: =$I$41 -> 44
A45: PM hours | B45: =IF($B$44=0,0,$B$44*'Global Assumptions'!$B$7) -> 15.4
A46: Project timeline (select) | B46: Standard (7+ weeks)
A47: Final hours (incl. PM + timeline multiplier) | B47: =($B$44+$B$45)*IF($B$46="5-7 weeks",'Global Assumptions'!$B$11,IF($B$46="3-4 weeks",'Global Assumptions'!$B$12,IF($B$46="<3 weeks",'Global Assumptions'!$B$13,'Global Assumptions'!$B$10))) -> 59.4
A48: Final cost ($) | B48: =$B$47*'Global Assumptions'!$B$6 -> 15325.2
A50: Sources reviewed: ⚠ Design/Build split still uses placeholder hours — reviewed Everlink SOW 004, Zimperium proposal, Zendesk Inc./GoFundMe/Gameday Men's Health, none give a phase-level hour breakdown. Update from a real hour-itemized Custom Help Center SOW as soon as one is available.

Sheet Voice
A1: Voice (OOB) Calculator
A2: WHAT'S INCLUDED: Out-of-the-box Zendesk Talk setup — discovery, phone number configuration, IVR build (scaled by complexity), and training/documentation/testing. Greetings are not recorded as part of this scope. No PM is applied on this tab per the original rate card note.
A4: MEETING CADENCE (informational — already reflected in the effort hours below; not additive)
A5: • Up to 1×30-min discovery/setup session per phone line.
A6: • Up to 1×1hr admin training session if this engagement is not bundled with a Support package.
A7: • If this engagement is standalone (not bundled with a Support package): +30-min kickoff, +30-min design sign-off (see Global Assumptions).
A9: SECTION 1 — ASSUMPTIONS (gray = calibrated reference values, not meant to be edited)
A10: Assumption | B10: Value | C10: Notes / Source
A11: Blended hourly rate ($) | B11: ='Global Assumptions'!$B$6 -> 258 | C11: Linked to Global Assumptions default rate.
A13: Discovery — flat hrs | B13: 1.5 | C13: From the original Voice rate card. This is Envoy's effort for the discovery phase — see the meeting cadence note above for how that time is spent.
A14: Hrs per phone number configured | B14: 1.5 | C14: From the original Voice rate card.
A15: Hrs per IVR — Normal complexity | B15: 1 | C15: From the original Voice rate card.
A16: Hrs per IVR — High complexity | B16: 4 | C16: From the original Voice rate card.
A17: Training / documentation / testing — flat hrs | B17: 7 | C17: From the original Voice rate card. This is Envoy's effort for training/doc/testing — see the meeting cadence note above for how that time is spent.
A19: SECTION 2 — CALCULATOR (add one row per scope; only edit columns A—D)
A20: Row below marked EXAMPLE is a sample entry — overwrite it. Columns E onward calculate automatically. No PM row on this tab — per the original rate card, no PM is needed for Voice OOB setup.
A21: Scope Name | B21: # Phone Numbers | C21: # IVRs | D21: IVR Complexity | E21: Discovery Hrs | F21: Config Hrs | G21: IVR Hrs | H21: Training Hrs | I21: Total Hrs
A22: Voice OOB Setup (EXAMPLE — overwrite) | B22: 2 | C22: 2 | D22: Normal | E22: =IF($A22="","",$B$13) -> 1.5 | F22: =IF($A22="","",$B22*$B$14) -> 3 | G22: =IF($A22="","",$C22*IF($D22="High",$B$16,$B$15)) -> 2 | H22: =IF($A22="","",$B$17) -> 7 | I22: =IF($A22="","",$E22+$F22+$G22+$H22) -> 13.5
E23: =IF($A23="","",$B$13) | F23: =IF($A23="","",$B23*$B$14) | G23: =IF($A23="","",$C23*IF($D23="High",$B$16,$B$15)) | H23: =IF($A23="","",$B$17) | I23: =IF($A23="","",$E23+$F23+$G23+$H23)
E24: =IF($A24="","",$B$13) | F24: =IF($A24="","",$B24*$B$14) | G24: =IF($A24="","",$C24*IF($D24="High",$B$16,$B$15)) | H24: =IF($A24="","",$B$17) | I24: =IF($A24="","",$E24+$F24+$G24+$H24)
E25: =IF($A25="","",$B$13) | F25: =IF($A25="","",$B25*$B$14) | G25: =IF($A25="","",$C25*IF($D25="High",$B$16,$B$15)) | H25: =IF($A25="","",$B$17) | I25: =IF($A25="","",$E25+$F25+$G25+$H25)
E26: =IF($A26="","",$B$13) | F26: =IF($A26="","",$B26*$B$14) | G26: =IF($A26="","",$C26*IF($D26="High",$B$16,$B$15)) | H26: =IF($A26="","",$B$17) | I26: =IF($A26="","",$E26+$F26+$G26+$H26)
E27: =IF($A27="","",$B$13) | F27: =IF($A27="","",$B27*$B$14) | G27: =IF($A27="","",$C27*IF($D27="High",$B$16,$B$15)) | H27: =IF($A27="","",$B$17) | I27: =IF($A27="","",$E27+$F27+$G27+$H27)
E28: =IF($A28="","",$B$13) | F28: =IF($A28="","",$B28*$B$14) | G28: =IF($A28="","",$C28*IF($D28="High",$B$16,$B$15)) | H28: =IF($A28="","",$B$17) | I28: =IF($A28="","",$E28+$F28+$G28+$H28)
E29: =IF($A29="","",$B$13) | F29: =IF($A29="","",$B29*$B$14) | G29: =IF($A29="","",$C29*IF($D29="High",$B$16,$B$15)) | H29: =IF($A29="","",$B$17) | I29: =IF($A29="","",$E29+$F29+$G29+$H29)
E30: =IF($A30="","",$B$13) | F30: =IF($A30="","",$B30*$B$14) | G30: =IF($A30="","",$C30*IF($D30="High",$B$16,$B$15)) | H30: =IF($A30="","",$B$17) | I30: =IF($A30="","",$E30+$F30+$G30+$H30)
E31: =IF($A31="","",$B$13) | F31: =IF($A31="","",$B31*$B$14) | G31: =IF($A31="","",$C31*IF($D31="High",$B$16,$B$15)) | H31: =IF($A31="","",$B$17) | I31: =IF($A31="","",$E31+$F31+$G31+$H31)
A32: TOTAL | B32: =SUM(B22:B31) -> 2 | C32: =SUM(C22:C31) -> 2 | E32: =SUM(E22:E31) -> 1.5 | F32: =SUM(F22:F31) -> 3 | G32: =SUM(G22:G31) -> 2 | H32: =SUM(H22:H31) -> 7 | I32: =SUM(I22:I31) -> 13.5
A34: SECTION 3 — RESULT (no PM applied — see note above)
A35: Total hours | B35: =$I$32 -> 13.5
A36: Project timeline (select) | B36: Standard (7+ weeks)
A37: Final hours (incl. timeline multiplier) | B37: =$B$35*IF($B$36="5-7 weeks",'Global Assumptions'!$B$11,IF($B$36="3-4 weeks",'Global Assumptions'!$B$12,IF($B$36="<3 weeks",'Global Assumptions'!$B$13,'Global Assumptions'!$B$10))) -> 13.5
A38: Final cost ($) | B38: =$B$37*'Global Assumptions'!$B$6 -> 3483
A40: Sources reviewed: original Sow Collab "Voice" tab.

Sheet OOB Messaging
A1: OOB Messaging Calculator
A2: WHAT'S INCLUDED: Out-of-the-box messaging widget setup (web messaging widget, plus other channel widgets like WhatsApp/Facebook), per brand. Does not include AIAA (bot) setup — see the AIAA tab for that.
A4: MEETING CADENCE (informational — already reflected in the effort hours below; not additive)
A5: • Up to 1×1hr session per widget (messaging + other channel combined).
A6: • If this engagement is standalone (not bundled with a Support package): +30-min kickoff, +30-min design sign-off (see Global Assumptions).
A8: SECTION 1 — ASSUMPTIONS (gray = calibrated reference values, not meant to be edited)
A9: Assumption | B9: Value | C9: Notes / Source
A10: Blended hourly rate ($) | B10: ='Global Assumptions'!$B$6 -> 258 | C10: Linked to Global Assumptions default rate.
A12: Messaging widget — flat hrs (first widget, per brand) | B12: 6 | C12: From the original OOB Messaging rate card.
A13: Messaging widget — additional hrs (each beyond the first, per brand) | B13: 2 | C13: From the original OOB Messaging rate card.
A14: Other channel widget (WhatsApp/FB, etc.) — flat hrs (first widget, per brand) | B14: 6 | C14: From the original OOB Messaging rate card.
A15: Other channel widget — additional hrs (each beyond the first, per brand) | B15: 2 | C15: From the original OOB Messaging rate card.
A16: TA guidance add-on — flat hrs | B16: 5 | C16: From the original OOB Messaging rate card ("requires a TA: 10 hours").
A18: SECTION 2 — CALCULATOR (add one row per scope; only edit columns A—D)
A19: Row below marked EXAMPLE is a sample entry — overwrite it. Columns E onward calculate automatically.
A20: Scope Name | B20: # Messaging Widgets | C20: # Other Channel Widgets | D20: Needs TA Guidance? (Y/N) | E20: — | F20: Widget Hrs | G20: TA Hrs | H20: Total Hrs
A21: Messaging Setup (EXAMPLE — overwrite) | B21: 1 | C21: 1 | D21: N | F21: =IF($A21="","",IF($B21>0,$B$12+MAX(0,$B21-1)*$B$13,0)+IF($C21>0,$B$14+MAX(0,$C21-1)*$B$15,0)) -> 12 | G21: =IF($A21="","",IF($D21="Y",$B$16,0)) -> 0 | H21: =IF($A21="","",$F21+$G21) -> 12
F22: =IF($A22="","",IF($B22>0,$B$12+MAX(0,$B22-1)*$B$13,0)+IF($C22>0,$B$14+MAX(0,$C22-1)*$B$15,0)) | G22: =IF($A22="","",IF($D22="Y",$B$16,0)) | H22: =IF($A22="","",$F22+$G22)
F23: =IF($A23="","",IF($B23>0,$B$12+MAX(0,$B23-1)*$B$13,0)+IF($C23>0,$B$14+MAX(0,$C23-1)*$B$15,0)) | G23: =IF($A23="","",IF($D23="Y",$B$16,0)) | H23: =IF($A23="","",$F23+$G23)
F24: =IF($A24="","",IF($B24>0,$B$12+MAX(0,$B24-1)*$B$13,0)+IF($C24>0,$B$14+MAX(0,$C24-1)*$B$15,0)) | G24: =IF($A24="","",IF($D24="Y",$B$16,0)) | H24: =IF($A24="","",$F24+$G24)
F25: =IF($A25="","",IF($B25>0,$B$12+MAX(0,$B25-1)*$B$13,0)+IF($C25>0,$B$14+MAX(0,$C25-1)*$B$15,0)) | G25: =IF($A25="","",IF($D25="Y",$B$16,0)) | H25: =IF($A25="","",$F25+$G25)
F26: =IF($A26="","",IF($B26>0,$B$12+MAX(0,$B26-1)*$B$13,0)+IF($C26>0,$B$14+MAX(0,$C26-1)*$B$15,0)) | G26: =IF($A26="","",IF($D26="Y",$B$16,0)) | H26: =IF($A26="","",$F26+$G26)
F27: =IF($A27="","",IF($B27>0,$B$12+MAX(0,$B27-1)*$B$13,0)+IF($C27>0,$B$14+MAX(0,$C27-1)*$B$15,0)) | G27: =IF($A27="","",IF($D27="Y",$B$16,0)) | H27: =IF($A27="","",$F27+$G27)
F28: =IF($A28="","",IF($B28>0,$B$12+MAX(0,$B28-1)*$B$13,0)+IF($C28>0,$B$14+MAX(0,$C28-1)*$B$15,0)) | G28: =IF($A28="","",IF($D28="Y",$B$16,0)) | H28: =IF($A28="","",$F28+$G28)
F29: =IF($A29="","",IF($B29>0,$B$12+MAX(0,$B29-1)*$B$13,0)+IF($C29>0,$B$14+MAX(0,$C29-1)*$B$15,0)) | G29: =IF($A29="","",IF($D29="Y",$B$16,0)) | H29: =IF($A29="","",$F29+$G29)
F30: =IF($A30="","",IF($B30>0,$B$12+MAX(0,$B30-1)*$B$13,0)+IF($C30>0,$B$14+MAX(0,$C30-1)*$B$15,0)) | G30: =IF($A30="","",IF($D30="Y",$B$16,0)) | H30: =IF($A30="","",$F30+$G30)
A31: TOTAL | B31: =SUM(B21:B30) -> 1 | C31: =SUM(C21:C30) -> 1 | F31: =SUM(F21:F30) -> 12 | G31: =SUM(G21:G30) -> 0 | H31: =SUM(H21:H30) -> 12
A33: SECTION 3 — RESULT
A34: Total hours (pre-PM) | B34: =$H$31 -> 12
A35: PM hours | B35: =IF($B$34=0,0,$B$34*'Global Assumptions'!$B$7) -> 4.2
A36: Project timeline (select) | B36: Standard (7+ weeks)
A37: Final hours (incl. PM + timeline multiplier) | B37: =($B$34+$B$35)*IF($B$36="5-7 weeks",'Global Assumptions'!$B$11,IF($B$36="3-4 weeks",'Global Assumptions'!$B$12,IF($B$36="<3 weeks",'Global Assumptions'!$B$13,'Global Assumptions'!$B$10))) -> 16.2
A38: Final cost ($) | B38: =$B$37*'Global Assumptions'!$B$6 -> 4179.6
A40: Sources reviewed: original Sow Collab "OOB Messaging" tab.

Sheet AI Copilot
A1: AI Copilot Calculator
A2: WHAT'S INCLUDED: Two tiers — simply turning on Copilot features (overview only, no config), or the fuller tier that also builds auto-assist procedures, reviews Copilot recommendations, and configures suggestions. No PM is applied for the "turning on features only" tier per the original rate card.
A4: MEETING CADENCE (informational — already reflected in the effort hours below; not additive)
A5: • Tier 1 (Product feature review): up to 1×1.5h session.
A6: • Tier 2 (Expanded effort): up to 1×1hr overview session + up to 2×1hr collaboration sessions.
A7: • If this engagement is standalone (not bundled with a Support package): +30-min kickoff, +30-min design sign-off (see Global Assumptions).
A9: SECTION 1 — ASSUMPTIONS (gray = calibrated reference values, not meant to be edited)
A10: Assumption | B10: Value | C10: Notes / Source
A11: Blended hourly rate ($) | B11: ='Global Assumptions'!$B$6 -> 258 | C11: Linked to Global Assumptions default rate.
A13: Tier 1 — Turning on features & overview — flat hrs | B13: 5 | C13: From the original AI Copilot rate card. No PM needed for this tier.
A14: Tier 2 — Above, plus procedures/best practices/entities/suggestion config — flat hrs TOTAL | B14: 15 | C14: From the original AI Copilot rate card. This is the total for the full tier, inclusive of the Tier-1 work — not additive on top of Tier 1.
A16: SECTION 2 — CALCULATOR (add one row per scope; only edit columns A—B)
A17: Row below marked EXAMPLE is a sample entry — overwrite it. Columns C onward calculate automatically. PM only applies to Tier 2 — Tier 1 carries no PM per the original rate card.
A18: Scope Name | B18: Tier | C18: — | D18: — | E18: — | F18: Hours | G18: PM Hrs | H18: Total Hrs
A19: AI Copilot Rollout (EXAMPLE — overwrite) | B19: Tier 1 — Enable only | F19: =IF($A19="","",IF($B19="Tier 2 — Enable + procedures/config",$B$14,$B$13)) -> 5 | G19: =IF($A19="","",IF($B19="Tier 2 — Enable + procedures/config",$F19*'Global Assumptions'!$B$7,0)) -> 0 | H19: =IF($A19="","",$F19+$G19) -> 5
F20: =IF($A20="","",IF($B20="Tier 2 — Enable + procedures/config",$B$14,$B$13)) | G20: =IF($A20="","",IF($B20="Tier 2 — Enable + procedures/config",$F20*'Global Assumptions'!$B$7,0)) | H20: =IF($A20="","",$F20+$G20)
F21: =IF($A21="","",IF($B21="Tier 2 — Enable + procedures/config",$B$14,$B$13)) | G21: =IF($A21="","",IF($B21="Tier 2 — Enable + procedures/config",$F21*'Global Assumptions'!$B$7,0)) | H21: =IF($A21="","",$F21+$G21)
F22: =IF($A22="","",IF($B22="Tier 2 — Enable + procedures/config",$B$14,$B$13)) | G22: =IF($A22="","",IF($B22="Tier 2 — Enable + procedures/config",$F22*'Global Assumptions'!$B$7,0)) | H22: =IF($A22="","",$F22+$G22)
F23: =IF($A23="","",IF($B23="Tier 2 — Enable + procedures/config",$B$14,$B$13)) | G23: =IF($A23="","",IF($B23="Tier 2 — Enable + procedures/config",$F23*'Global Assumptions'!$B$7,0)) | H23: =IF($A23="","",$F23+$G23)
F24: =IF($A24="","",IF($B24="Tier 2 — Enable + procedures/config",$B$14,$B$13)) | G24: =IF($A24="","",IF($B24="Tier 2 — Enable + procedures/config",$F24*'Global Assumptions'!$B$7,0)) | H24: =IF($A24="","",$F24+$G24)
F25: =IF($A25="","",IF($B25="Tier 2 — Enable + procedures/config",$B$14,$B$13)) | G25: =IF($A25="","",IF($B25="Tier 2 — Enable + procedures/config",$F25*'Global Assumptions'!$B$7,0)) | H25: =IF($A25="","",$F25+$G25)
F26: =IF($A26="","",IF($B26="Tier 2 — Enable + procedures/config",$B$14,$B$13)) | G26: =IF($A26="","",IF($B26="Tier 2 — Enable + procedures/config",$F26*'Global Assumptions'!$B$7,0)) | H26: =IF($A26="","",$F26+$G26)
F27: =IF($A27="","",IF($B27="Tier 2 — Enable + procedures/config",$B$14,$B$13)) | G27: =IF($A27="","",IF($B27="Tier 2 — Enable + procedures/config",$F27*'Global Assumptions'!$B$7,0)) | H27: =IF($A27="","",$F27+$G27)
F28: =IF($A28="","",IF($B28="Tier 2 — Enable + procedures/config",$B$14,$B$13)) | G28: =IF($A28="","",IF($B28="Tier 2 — Enable + procedures/config",$F28*'Global Assumptions'!$B$7,0)) | H28: =IF($A28="","",$F28+$G28)
A29: TOTAL | F29: =SUM(F19:F28) -> 5 | G29: =SUM(G19:G28) -> 0 | H29: =SUM(H19:H28) -> 5
A31: SECTION 3 — RESULT
A32: Total hours (incl. per-row PM) | B32: =$H$29 -> 5
A33: Project timeline (select) | B33: Standard (7+ weeks)
A34: Final hours (incl. timeline multiplier) | B34: =$B$32*IF($B$33="5-7 weeks",'Global Assumptions'!$B$11,IF($B$33="3-4 weeks",'Global Assumptions'!$B$12,IF($B$33="<3 weeks",'Global Assumptions'!$B$13,'Global Assumptions'!$B$10))) -> 5
A35: Final cost ($) | B35: =$B$34*'Global Assumptions'!$B$6 -> 1290
A37: Sources reviewed: original Sow Collab "AI Copilot" tab.

Sheet AIAA
A1: AIAA Calculator
A2: WHAT'S INCLUDED: AI Agents/Advanced Automation setup — source connection & discovery, build of up to 3 standard-size custom use cases (no more than 20 blocks per procedure/dialogue), 2 included API connections/action flows, Zendesk support routing for the messaging channel, and TA guidance time. PM is only needed if the project exceeds 40 total hours or isn't standalone.
A4: MEETING CADENCE (informational — already reflected in the effort hours below; not additive)
A5: • Up to 1 session for source connection & initial bot-testing objectives.
A6: • Up to 3×1hr collaboration sessions (including testing discussions).
A7: • Up to 1×1hr admin training session if not bundled with a Support package.
A8: • If this engagement is standalone (not bundled with a Support package): +30-min kickoff, +30-min design sign-off (see Global Assumptions).
A10: SECTION 1 — ASSUMPTIONS (gray = calibrated reference values, not meant to be edited)
A11: Assumption | B11: Value | C11: Notes / Source
A12: Blended hourly rate ($) | B12: ='Global Assumptions'!$B$6 -> 258 | C12: Linked to Global Assumptions default rate.
A14: BASELINE (flat, included in every scope)
A15: Connect sources & discovery (3× 1-hr sessions) — flat hrs | B15: 8 | C15: From the original AIAA rate card. This is Envoy's effort for the connect/discovery phase — see the meeting cadence note above for how that time is spent.
A16: Build up to 3 standard use cases — flat hrs | B16: 8 | C16: From the original AIAA rate card. Standard = no more than 20 blocks per procedure/dialogue.
A17: ZD support routing for messaging channel — flat hrs | B17: 5 | C17: From the original AIAA rate card.
A18: TA time for guidance — flat hrs | B18: 5 | C18: From the original AIAA rate card.
A20: INCLUDED ALLOWANCES
A21: # API connections/action flows included | B21: 2 | C21: From the original AIAA rate card.
A22: # use cases included | B22: 3 | C22: From the original AIAA rate card.
A24: ADD-ONS
A25: Hrs per additional API connection/action flow (beyond included) | B25: 3 | C25: From the original AIAA rate card.
A26: Hrs per additional use case (beyond included) | B26: 3 | C26: From the original AIAA rate card.
A28: PM THRESHOLD
A29: PM-required hour threshold | B29: 40 | C29: No PM needed if standalone and under this many total hours; projects over this threshold should include a PM. From the original AIAA rate card.
A31: SECTION 2 — CALCULATOR (add one row per scope; only edit columns A—C)
A32: Row below marked EXAMPLE is a sample entry — overwrite it. Columns D onward calculate automatically.
A33: Scope Name | B33: # API Connections/ Action Flows | C33: # Use Cases | D33: Baseline Hrs | E33: Add-on Hrs | F33: PM Hrs | G33: — | H33: Total Hrs
A34: AIAA Rollout (EXAMPLE — overwrite) | B34: 2 | C34: 3 | D34: =IF($A34="","",$B$15+$B$16+$B$17+$B$18) -> 26 | E34: =IF($A34="","",MAX(0,$B34-$B$21)*$B$25+MAX(0,$C34-$B$22)*$B$26) -> 0 | F34: =IF($A34="","",IF(($D34+$E34)>$B$29,($D34+$E34)*'Global Assumptions'!$B$7,0)) -> 0 | H34: =IF($A34="","",$D34+$E34+$F34) -> 26
D35: =IF($A35="","",$B$15+$B$16+$B$17+$B$18) | E35: =IF($A35="","",MAX(0,$B35-$B$21)*$B$25+MAX(0,$C35-$B$22)*$B$26) | F35: =IF($A35="","",IF(($D35+$E35)>$B$29,($D35+$E35)*'Global Assumptions'!$B$7,0)) | H35: =IF($A35="","",$D35+$E35+$F35)
D36: =IF($A36="","",$B$15+$B$16+$B$17+$B$18) | E36: =IF($A36="","",MAX(0,$B36-$B$21)*$B$25+MAX(0,$C36-$B$22)*$B$26) | F36: =IF($A36="","",IF(($D36+$E36)>$B$29,($D36+$E36)*'Global Assumptions'!$B$7,0)) | H36: =IF($A36="","",$D36+$E36+$F36)
D37: =IF($A37="","",$B$15+$B$16+$B$17+$B$18) | E37: =IF($A37="","",MAX(0,$B37-$B$21)*$B$25+MAX(0,$C37-$B$22)*$B$26) | F37: =IF($A37="","",IF(($D37+$E37)>$B$29,($D37+$E37)*'Global Assumptions'!$B$7,0)) | H37: =IF($A37="","",$D37+$E37+$F37)
D38: =IF($A38="","",$B$15+$B$16+$B$17+$B$18) | E38: =IF($A38="","",MAX(0,$B38-$B$21)*$B$25+MAX(0,$C38-$B$22)*$B$26) | F38: =IF($A38="","",IF(($D38+$E38)>$B$29,($D38+$E38)*'Global Assumptions'!$B$7,0)) | H38: =IF($A38="","",$D38+$E38+$F38)
D39: =IF($A39="","",$B$15+$B$16+$B$17+$B$18) | E39: =IF($A39="","",MAX(0,$B39-$B$21)*$B$25+MAX(0,$C39-$B$22)*$B$26) | F39: =IF($A39="","",IF(($D39+$E39)>$B$29,($D39+$E39)*'Global Assumptions'!$B$7,0)) | H39: =IF($A39="","",$D39+$E39+$F39)
D40: =IF($A40="","",$B$15+$B$16+$B$17+$B$18) | E40: =IF($A40="","",MAX(0,$B40-$B$21)*$B$25+MAX(0,$C40-$B$22)*$B$26) | F40: =IF($A40="","",IF(($D40+$E40)>$B$29,($D40+$E40)*'Global Assumptions'!$B$7,0)) | H40: =IF($A40="","",$D40+$E40+$F40)
D41: =IF($A41="","",$B$15+$B$16+$B$17+$B$18) | E41: =IF($A41="","",MAX(0,$B41-$B$21)*$B$25+MAX(0,$C41-$B$22)*$B$26) | F41: =IF($A41="","",IF(($D41+$E41)>$B$29,($D41+$E41)*'Global Assumptions'!$B$7,0)) | H41: =IF($A41="","",$D41+$E41+$F41)
D42: =IF($A42="","",$B$15+$B$16+$B$17+$B$18) | E42: =IF($A42="","",MAX(0,$B42-$B$21)*$B$25+MAX(0,$C42-$B$22)*$B$26) | F42: =IF($A42="","",IF(($D42+$E42)>$B$29,($D42+$E42)*'Global Assumptions'!$B$7,0)) | H42: =IF($A42="","",$D42+$E42+$F42)
D43: =IF($A43="","",$B$15+$B$16+$B$17+$B$18) | E43: =IF($A43="","",MAX(0,$B43-$B$21)*$B$25+MAX(0,$C43-$B$22)*$B$26) | F43: =IF($A43="","",IF(($D43+$E43)>$B$29,($D43+$E43)*'Global Assumptions'!$B$7,0)) | H43: =IF($A43="","",$D43+$E43+$F43)
A44: TOTAL | B44: =SUM(B34:B43) -> 2 | C44: =SUM(C34:C43) -> 3 | D44: =SUM(D34:D43) -> 26 | E44: =SUM(E34:E43) -> 0 | F44: =SUM(F34:F43) -> 0 | H44: =SUM(H34:H43) -> 26
A46: SECTION 3 — RESULT (PM already applied per-row above the 40-hr threshold)
A47: Total hours (incl. per-row PM) | B47: =$H$44 -> 26
A48: Project timeline (select) | B48: Standard (7+ weeks)
...

Sheet QA
A1: QA Calculator
A2: WHAT'S INCLUDED: Up to 2 scorecards (8 rating categories each, plus 5 custom autoscoring categories), 2 workspaces (up to 4 standard roles), AutoQA (up to 6 autoscoring categories, 1 saved dashboard view), up to 2 Spotlight filters, up to 8 agent groups, and calibration/coaching (methodology only — two 30-minute sessions; Envoy does not run live calibration or author coaching content). No PM is applied on this tab per the original rate card.
A4: MEETING CADENCE (informational — already reflected in the effort hours below; not additive)
A5: • Up to 4×1hr collaboration sessions.
A6: • If this engagement is standalone (not bundled with a Support package): +30-min kickoff, +30-min design sign-off (see Global Assumptions).
A8: SECTION 1 — ASSUMPTIONS (gray = calibrated reference values, not meant to be edited)
A9: Assumption | B9: Value | C9: Notes / Source
A10: Blended hourly rate ($) | B10: ='Global Assumptions'!$B$6 -> 258 | C10: Linked to Global Assumptions default rate.
A12: BASELINE (flat, included in every scope — sums to 20 hrs)
A13: Discovery — flat hrs | B13: 5 | C13: From the original QA rate card.
A14: Scorecard & rating categories — flat hrs | B14: 1 | C14: From the original QA rate card.
A15: AutoQA — flat hrs | B15: 1 | C15: From the original QA rate card.
A16: Spotlight & review workflows — flat hrs | B16: 1 | C16: From the original QA rate card.
A17: Calibration & coaching — flat hrs | B17: 1 | C17: Methodology only — Envoy does not run live calibration or author coaching content.
A18: Dashboards — flat hrs | B18: 2 | C18: From the original QA rate card.
A19: Config — flat hrs | B19: 4 | C19: From the original QA rate card.
A21: INCLUDED ALLOWANCES
A22: # workspaces included | B22: 2 | C22: From the original QA rate card.
A23: # scorecards included | B23: 2 | C23: From the original QA rate card.
A25: ADD-ONS
A26: Hrs per additional workspace (beyond included) | B26: 1 | C26: From the original QA rate card.
A27: Hrs per additional scorecard, up to 5 rating categories (beyond included) | B27: 1 | C27: From the original QA rate card.
A29: SECTION 2 — CALCULATOR (add one row per scope; only edit columns A—C)
A30: Row below marked EXAMPLE is a sample entry — overwrite it. Columns D onward calculate automatically.
A31: Scope Name | B31: # Total Workspaces | C31: # Total Scorecards | D31: Baseline Hrs | E31: Add-on Hrs | F31: — | G31: — | H31: Total Hrs
A32: QA Program Setup (EXAMPLE — overwrite) | B32: 2 | C32: 2 | D32: =IF($A32="","",$B$13+$B$14+$B$15+$B$16+$B$17+$B$18+$B$19) -> 15 | E32: =IF($A32="","",MAX(0,$B32-$B$22)*$B$26+MAX(0,$C32-$B$23)*$B$27) -> 0 | H32: =IF($A32="","",$D32+$E32) -> 15
D33: =IF($A33="","",$B$13+$B$14+$B$15+$B$16+$B$17+$B$18+$B$19) | E33: =IF($A33="","",MAX(0,$B33-$B$22)*$B$26+MAX(0,$C33-$B$23)*$B$27) | H33: =IF($A33="","",$D33+$E33)
D34: =IF($A34="","",$B$13+$B$14+$B$15+$B$16+$B$17+$B$18+$B$19) | E34: =IF($A34="","",MAX(0,$B34-$B$22)*$B$26+MAX(0,$C34-$B$23)*$B$27) | H34: =IF($A34="","",$D34+$E34)
D35: =IF($A35="","",$B$13+$B$14+$B$15+$B$16+$B$17+$B$18+$B$19) | E35: =IF($A35="","",MAX(0,$B35-$B$22)*$B$26+MAX(0,$C35-$B$23)*$B$27) | H35: =IF($A35="","",$D35+$E35)
D36: =IF($A36="","",$B$13+$B$14+$B$15+$B$16+$B$17+$B$18+$B$19) | E36: =IF($A36="","",MAX(0,$B36-$B$22)*$B$26+MAX(0,$C36-$B$23)*$B$27) | H36: =IF($A36="","",$D36+$E36)
D37: =IF($A37="","",$B$13+$B$14+$B$15+$B$16+$B$17+$B$18+$B$19) | E37: =IF($A37="","",MAX(0,$B37-$B$22)*$B$26+MAX(0,$C37-$B$23)*$B$27) | H37: =IF($A37="","",$D37+$E37)
D38: =IF($A38="","",$B$13+$B$14+$B$15+$B$16+$B$17+$B$18+$B$19) | E38: =IF($A38="","",MAX(0,$B38-$B$22)*$B$26+MAX(0,$C38-$B$23)*$B$27) | H38: =IF($A38="","",$D38+$E38)
D39: =IF($A39="","",$B$13+$B$14+$B$15+$B$16+$B$17+$B$18+$B$19) | E39: =IF($A39="","",MAX(0,$B39-$B$22)*$B$26+MAX(0,$C39-$B$23)*$B$27) | H39: =IF($A39="","",$D39+$E39)
D40: =IF($A40="","",$B$13+$B$14+$B$15+$B$16+$B$17+$B$18+$B$19) | E40: =IF($A40="","",MAX(0,$B40-$B$22)*$B$26+MAX(0,$C40-$B$23)*$B$27) | H40: =IF($A40="","",$D40+$E40)
D41: =IF($A41="","",$B$13+$B$14+$B$15+$B$16+$B$17+$B$18+$B$19) | E41: =IF($A41="","",MAX(0,$B41-$B$22)*$B$26+MAX(0,$C41-$B$23)*$B$27) | H41: =IF($A41="","",$D41+$E41)
A42: TOTAL | B42: =SUM(B32:B41) -> 2 | C42: =SUM(C32:C41) -> 2 | D42: =SUM(D32:D41) -> 15 | E42: =SUM(E32:E41) -> 0 | H42: =SUM(H32:H41) -> 15
A44: SECTION 3 — RESULT (no PM applied — see note above)
A45: Total hours | B45: =$H$42 -> 15
A46: Project timeline (select) | B46: Standard (7+ weeks)
A47: Final hours (incl. timeline multiplier) | B47: =$B$45*IF($B$46="5-7 weeks",'Global Assumptions'!$B$11,IF($B$46="3-4 weeks",'Global Assumptions'!$B$12,IF($B$46="<3 weeks",'Global Assumptions'!$B$13,'Global Assumptions'!$B$10))) -> 15
...

Sheet WFM
A1: WFM Calculator
A2: WHAT'S INCLUDED: Workforce Management setup — discovery, configuration, UAT/soft launch/training, and hypercare. Discovery and Config both scale with the number of Agent Teams. Up to 4 workstreams are included; each additional workstream is a flat add-on.
A4: MEETING CADENCE (informational — already reflected in the effort hours below; not additive)
A5: • If this engagement is standalone (not bundled with a Support package): +30-min kickoff, +30-min design sign-off (see Global Assumptions).
A7: SECTION 1 — ASSUMPTIONS (gray = calibrated reference values, not meant to be edited)
A8: Assumption | B8: Value | C8: Notes / Source
A9: Blended hourly rate ($) | B9: ='Global Assumptions'!$B$6 -> 258 | C9: Linked to Global Assumptions default rate.
A11: BASELINE (flat, included in every scope)
A12: Discovery — base flat hrs | B12: 6 | C12: Reconstructed from the original rate card: base 6 hrs + 1.5 hrs per Agent Team. At 1 Agent Team this reproduces the original flat 7.5-hr Discovery figure exactly.
A13: Discovery — hrs per Agent Team | B13: 1.5 | C13: See note above.
A14: Config — base flat hrs | B14: 6 | C14: Reconstructed from the original rate card: base 6 hrs + 1 hr per Agent Team. At 1 Agent Team this reproduces the original flat 7-hr Config figure exactly.
A15: Config — hrs per Agent Team | B15: 1 | C15: See note above.
A16: UAT / soft launch / training — flat hrs | B16: 6 | C16: From the original WFM rate card.
A17: Hypercare — flat hrs | B17: 2 | C17: From the original WFM rate card.
A19: INCLUDED ALLOWANCE
A20: # workstreams included | B20: 4 | C20: From the original WFM rate card.
A22: ADD-ONS
A23: Hrs per additional workstream (beyond included) | B23: 2 | C23: From the original WFM rate card.
A25: SECTION 2 — CALCULATOR (add one row per scope; only edit columns A—C)
A26: Row below marked EXAMPLE is a sample entry — overwrite it. Columns D onward calculate automatically.
A27: Scope Name | B27: # Total Workstreams | C27: # Agent Teams | D27: Baseline Hrs | E27: Add-on Hrs | F27: — | G27: — | H27: Total Hrs
A28: WFM Rollout (EXAMPLE — overwrite) | B28: 4 | C28: 1 | D28: =IF($A28="","",$B$12+$C28*$B$13+$B$14+$C28*$B$15+$B$16+$B$17) -> 22.5 | E28: =IF($A28="","",MAX(0,$B28-$B$20)*$B$23) -> 0 | H28: =IF($A28="","",$D28+$E28) -> 22.5
D29: =IF($A29="","",$B$12+$C29*$B$13+$B$14+$C29*$B$15+$B$16+$B$17) | E29: =IF($A29="","",MAX(0,$B29-$B$20)*$B$23) | H29: =IF($A29="","",$D29+$E29)
D30: =IF($A30="","",$B$12+$C30*$B$13+$B$14+$C30*$B$15+$B$16+$B$17) | E30: =IF($A30="","",MAX(0,$B30-$B$20)*$B$23) | H30: =IF($A30="","",$D30+$E30)
D31: =IF($A31="","",$B$12+$C31*$B$13+$B$14+$C31*$B$15+$B$16+$B$17) | E31: =IF($A31="","",MAX(0,$B31-$B$20)*$B$23) | H31: =IF($A31="","",$D31+$E31)
D32: =IF($A32="","",$B$12+$C32*$B$13+$B$14+$C32*$B$15+$B$16+$B$17) | E32: =IF($A32="","",MAX(0,$B32-$B$20)*$B$23) | H32: =IF($A32="","",$D32+$E32)
D33: =IF($A33="","",$B$12+$C33*$B$13+$B$14+$C33*$B$15+$B$16+$B$17) | E33: =IF($A33="","",MAX(0,$B33-$B$20)*$B$23) | H33: =IF($A33="","",$D33+$E33)
D34: =IF($A34="","",$B$12+$C34*$B$13+$B$14+$C34*$B$15+$B$16+$B$17) | E34: =IF($A34="","",MAX(0,$B34-$B$20)*$B$23) | H34: =IF($A34="","",$D34+$E34)
D35: =IF($A35="","",$B$12+$C35*$B$13+$B$14+$C35*$B$15+$B$16+$B$17) | E35: =IF($A35="","",MAX(0,$B35-$B$20)*$B$23) | H35: =IF($A35="","",$D35+$E35)
D36: =IF($A36="","",$B$12+$C36*$B$13+$B$14+$C36*$B$15+$B$16+$B$17) | E36: =IF($A36="","",MAX(0,$B36-$B$20)*$B$23) | H36: =IF($A36="","",$D36+$E36)
D37: =IF($A37="","",$B$12+$C37*$B$13+$B$14+$C37*$B$15+$B$16+$B$17) | E37: =IF($A37="","",MAX(0,$B37-$B$20)*$B$23) | H37: =IF($A37="","",$D37+$E37)
A38: TOTAL | B38: =SUM(B28:B37) -> 4 | C38: =SUM(C28:C37) -> 1 | D38: =SUM(D28:D37) -> 22.5 | E38: =SUM(E28:E37) -> 0 | H38: =SUM(H28:H37) -> 22.5
A40: SECTION 3 — RESULT
A41: Total hours (pre-PM) | B41: =$H$38 -> 22.5
A42: PM hours | B42: =IF($B$41=0,0,$B$41*'Global Assumptions'!$B$7) -> 7.875
A43: Project timeline (select) | B43: Standard (7+ weeks)
A44: Final hours (incl. PM + timeline multiplier) | B44: =($B$41+$B$42)*IF($B$43="5-7 weeks",'Global Assumptions'!$B$11,IF($B$43="3-4 weeks",'Global Assumptions'!$B$12,IF($B$43="<3 weeks",'Global Assumptions'!$B$13,'Global Assumptions'!$B$10))) -> 30.375
A45: Final cost ($) | B45: =$B$44*'Global Assumptions'!$B$6 -> 7836.75
A47: Sources reviewed: original Sow Collab "WFM" tab.

Sheet Adv Data Privacy
A1: Advanced Data Privacy Calculator
A2: WHAT'S INCLUDED: Two engagement types — a quick Feature Review (assess ADPP add-on status and readiness only), or the Full Implementation walking through all 6 phases: Discovery & Readiness, Access Request & Portal Setup, KMS Configuration, Sandbox Testing, Production Rollout, and Documentation & Handoff. Client owns their own KMS-side configuration and ongoing key management throughout.
A4: MEETING CADENCE (informational — already reflected in the effort hours below; not additive)
A5: • Feature Review: up to 1×1hr additional session.
A6: • Full Implementation: up to 2×1hr discovery sessions, up to 3×1hr configuration guidance sessions, up to 2×1hr testing guidance sessions, up to 1×1hr go-live checklist/approval meeting.
A7: • If this engagement is standalone (not bundled with a Support package): +30-min kickoff, +30-min design sign-off (see Global Assumptions).
A9: SECTION 1 — ASSUMPTIONS (gray = calibrated reference values, not meant to be edited)
A10: Assumption | B10: Value | C10: Notes / Source
A11: Blended hourly rate ($) | B11: ='Global Assumptions'!$B$6 -> 258 | C11: Linked to Global Assumptions default rate.
A13: Feature Review — flat hrs | B13: 2 | C13: Quick assessment only: confirm ADPP add-on is active, review current data/field usage, flag known limitations. From the original Adv Data Privacy rate card.
A15: FULL IMPLEMENTATION — 6 PHASES
A16: Phase 1: Discovery & Readiness — flat hrs | B16: 2 | C16: Confirm KMS provider (AWS/Azure/GCP/Thales), flag known limitations (no key rotation support, possible feature degradation).
A17: Phase 2: Access Request & Portal Setup — flat hrs | B17: 2 | C17: Submit access request in Admin Center, track invitation (expires in 7 days), coordinate with client's KMS owner.
A18: Phase 3: KMS Configuration — hrs (most variable phase; original range 6–10 hrs) | B18: 8 | C18: Guide client through linking their KMS in the Secure Configuration Portal. Client owns actual KMS-side configuration. Editable — set to the midpoint of the original 6–10 hr range.
A19: Phase 4: Sandbox Testing — flat hrs | B19: 6 | C19: Turn on advanced encryption in sandbox, test across affected fields, document degraded functionality, validate with stakeholders.
A20: Phase 5: Production Rollout — hrs (original range 3–5 hrs) | B20: 4 | C20: Enable in production, confirm backfill encrypts correctly, monitor for issues. Editable — set to the midpoint of the original 3–5 hr range.
A21: Phase 6: Documentation & Handoff — hrs (original range 2–3 hrs) | B21: 2.5 | C21: Deliver config/decisions doc; client owns ongoing KMS key management going forward. Editable — set to the midpoint of the original 2–3 hr range.
A23: SECTION 2 — CALCULATOR (add one row per scope; only edit columns A—B)
A24: Row below marked EXAMPLE is a sample entry — overwrite it. Columns C onward calculate automatically.
A25: Scope Name | B25: Engagement Type | C25: — | D25: — | E25: PM Hrs | F25: — | G25: — | H25: Total Hrs
A26: ADPP Rollout (EXAMPLE — overwrite) | B26: Full Implementation | H26: =IF($A26="","",IF($B26="Feature Review",$B$13,$B$16+$B$17+$B$18+$B$19+$B$20+$B$21)) -> 24.5
H27: =IF($A27="","",IF($B27="Feature Review",$B$13,$B$16+$B$17+$B$18+$B$19+$B$20+$B$21))
H28: =IF($A28="","",IF($B28="Feature Review",$B$13,$B$16+$B$17+$B$18+$B$19+$B$20+$B$21))
H29: =IF($A29="","",IF($B29="Feature Review",$B$13,$B$16+$B$17+$B$18+$B$19+$B$20+$B$21))
H30: =IF($A30="","",IF($B30="Feature Review",$B$13,$B$16+$B$17+$B$18+$B$19+$B$20+$B$21))
H31: =IF($A31="","",IF($B31="Feature Review",$B$13,$B$16+$B$17+$B$18+$B$19+$B$20+$B$21))
H32: =IF($A32="","",IF($B32="Feature Review",$B$13,$B$16+$B$17+$B$18+$B$19+$B$20+$B$21))
